Workbook
Name CalendárioAno1: #REF!
Name CalendárioAno10: #REF!
Name CalendárioAno11: #REF!
Name CalendárioAno12: #REF!
Name CalendárioAno2: #REF!
Name CalendárioAno3: #REF!
Name CalendárioAno4: #REF!
Name CalendárioAno5: #REF!
Name CalendárioAno6: #REF!
Name CalendárioAno7: #REF!
Name CalendárioAno8: #REF!
Name CalendárioAno9: #REF!
Name CaléndárioMês1: #REF!
Name CaléndárioMês10: #REF!
Name CaléndárioMês10Opção: MATCH([0]!CaléndárioMês10,[0]!Meses,0)
Name CaléndárioMês10Opção: MATCH([0]!CaléndárioMês10,[0]!Meses,0)
Name CaléndárioMês10Opção: MATCH([0]!CaléndárioMês10,[0]!Meses,0)
Name CaléndárioMês10Opção: MATCH([0]!CaléndárioMês10,[0]!Meses,0)
Name CaléndárioMês10Opção: MATCH([0]!CaléndárioMês10,[0]!Meses,0)
Name CaléndárioMês10Opção: MATCH([0]!CaléndárioMês10,[0]!Meses,0)
Name CaléndárioMês10Opção: MATCH([0]!CaléndárioMês10,[0]!Meses,0)
Name CaléndárioMês10Opção: MATCH([0]!CaléndárioMês10,[0]!Meses,0)
Name CaléndárioMês10Opção: MATCH([0]!CaléndárioMês10,[0]!Meses,0)
Name CaléndárioMês10Opção: MATCH([0]!CaléndárioMês10,[0]!Meses,0)
Name CaléndárioMês10Opção: MATCH([0]!CaléndárioMês10,[0]!Meses,0)
Name CaléndárioMês10Opção: MATCH([0]!CaléndárioMês10,[0]!Meses,0)
Name CaléndárioMês10Opção: MATCH([0]!CaléndárioMês10,[0]!Meses,0)
Name CaléndárioMês10Opção: MATCH([0]!CaléndárioMês10,[0]!Meses,0)
Name CaléndárioMês10Opção: MATCH([0]!CaléndárioMês10,[0]!Meses,0)
Name CaléndárioMês10Opção: MATCH([0]!CaléndárioMês10,[0]!Meses,0)
Name CaléndárioMês10Opção: MATCH([0]!CaléndárioMês10,[0]!Meses,0)
Name CaléndárioMês10Opção: MATCH([0]!CaléndárioMês10,[0]!Meses,0)
Name CaléndárioMês10Opção: MATCH([0]!CaléndárioMês10,[0]!Meses,0)
Name CaléndárioMês10Opção: MATCH([0]!CaléndárioMês10,[0]!Meses,0)
Name CaléndárioMês10Opção: MATCH([0]!CaléndárioMês10,[0]!Meses,0)
Name CaléndárioMês10Opção: MATCH([0]!CaléndárioMês10,[0]!Meses,0)
Name CaléndárioMês10Opção: MATCH(CaléndárioMês10,Meses,0)
Name CaléndárioMês11: #REF!
Name CaléndárioMês11Opção: MATCH([0]!CaléndárioMês11,[0]!Meses,0)
Name CaléndárioMês11Opção: MATCH([0]!CaléndárioMês11,[0]!Meses,0)
Name CaléndárioMês11Opção: MATCH([0]!CaléndárioMês11,[0]!Meses,0)
Name CaléndárioMês11Opção: MATCH([0]!CaléndárioMês11,[0]!Meses,0)
Name CaléndárioMês11Opção: MATCH([0]!CaléndárioMês11,[0]!Meses,0)
Name CaléndárioMês11Opção: MATCH([0]!CaléndárioMês11,[0]!Meses,0)
Name CaléndárioMês11Opção: MATCH([0]!CaléndárioMês11,[0]!Meses,0)
Name CaléndárioMês11Opção: MATCH([0]!CaléndárioMês11,[0]!Meses,0)
Name CaléndárioMês11Opção: MATCH([0]!CaléndárioMês11,[0]!Meses,0)
Name CaléndárioMês11Opção: MATCH([0]!CaléndárioMês11,[0]!Meses,0)
Name CaléndárioMês11Opção: MATCH([0]!CaléndárioMês11,[0]!Meses,0)
Name CaléndárioMês11Opção: MATCH([0]!CaléndárioMês11,[0]!Meses,0)
Name CaléndárioMês11Opção: MATCH([0]!CaléndárioMês11,[0]!Meses,0)
Name CaléndárioMês11Opção: MATCH([0]!CaléndárioMês11,[0]!Meses,0)
Name CaléndárioMês11Opção: MATCH([0]!CaléndárioMês11,[0]!Meses,0)
Name CaléndárioMês11Opção: MATCH([0]!CaléndárioMês11,[0]!Meses,0)
Name CaléndárioMês11Opção: MATCH([0]!CaléndárioMês11,[0]!Meses,0)
Name CaléndárioMês11Opção: MATCH([0]!CaléndárioMês11,[0]!Meses,0)
Name CaléndárioMês11Opção: MATCH([0]!CaléndárioMês11,[0]!Meses,0)
Name CaléndárioMês11Opção: MATCH([0]!CaléndárioMês11,[0]!Meses,0)
Name CaléndárioMês11Opção: MATCH([0]!CaléndárioMês11,[0]!Meses,0)
Name CaléndárioMês11Opção: MATCH([0]!CaléndárioMês11,[0]!Meses,0)

Sheet 01
A1: RELATÓRIO KPI - Zona Sul BENASSI
A2: REDES / FILIAIS | B2: MOTORISTA | C2: PLACA | D2: SAIDA CD | E2: CHD LOJA | F2: SAIDA LOJA | H2: TEMPOI EM LOJA 1
A3: Zona Sul Loja 36 - Botafogo | B3: SIDNEI / AGNALDO | C3: LKR-5990 | D3: 0.22222222 | E3: 0.26736111 | F3: 0.32986111 | H3: =MOD(F3-E3, 1) -> 0.0625
A4: Zona Sul Loja 33 - Humaitá | B4: FÁBIO P. / LUIZ ALBERTO | C4: KQY-9E24 | D4: 0.21875 | E4: 0.24305556 | F4: 0.30208333 | H4: =MOD(F4-E4, 1) -> 0.059027778
A5: Zona Sul Loja 30 - Laranjeiras | B5: SIDNEI ANTONIO MENDES | C5: LQE-5401 | D5: 0.1875 | E5: 0.20486111 | F5: 0.23263889 | H5: =MOD(F5-E5, 1) -> 0.027777778
A6: Zona Sul Loja 21 - Flamengo | B6: JOSUE DOS SANTOS | C6: BBH-1C94 | D6: 0.25694444 | E6: 0.28125 | F6: 0.32986111 | H6: =MOD(F6-E6, 1) -> 0.048611111
A7: Zona Sul Loja 04 - Copacabana II | B7: SANDRO EDUARDO/ MARCIO | C7: KVH-9J42 | D7: 0.30902778 | E7: 0.35763889 | F7: 0.37152778 | H7: =MOD(F7-E7, 1) -> 0.013888889
A8: Zona Sul Loja 18 - Copacabana | B8: ALEX | C8: LKW-2B80 | D8: 0.21875 | E8: 0.25347222 | F8: 0.31944444 | H8: =MOD(F8-E8, 1) -> 0.065972222
A9: Zona Sul Loja 07 - Leblon | B9: RAPHAEL /LUIZ ALVES | C9: LCO-0978 | D9: 0.25347222 | E9: 0.28472222 | F9: 0.38194444 | H9: =MOD(F9-E9, 1) -> 0.097222222
A10: Zona Sul Loja 48 - Recreio | B10: FRANCISCO IRAN | C10: RJL-7D33 | D10: 0.14583333 | E10: 0.18055556 | F10: 0.29513889 | H10: =MOD(F10-E10, 1) -> 0.11458333
A11: Zona Sul Loja 13 - Angra | B11: DOUGLAS | C11: CZB-9J19 | D11: 0 | E11: 0.26736111 | F11: 0.30555556 | H11: =MOD(F11-E11, 1) -> 0.038194444
A12: Zona Sul Loja 28 - Urca | B12: HLOG / FABRICIO | C12: TML-7D21 | D12: 0.64583333 | E12: 0.6875 | F12: 0.72222222 | H12: =MOD(F12-E12, 1) -> 0.034722222
A13: Zona Sul Loja 29 - Flamengo | B13: HLOG / FABRICIO | C13: TML-7D21 | D13: 0.64583333 | E13: 0.73263889 | F13: 0.74305556 | H13: =MOD(F13-E13, 1) -> 0.010416667
A14: Zona Sul Loja 08 - Ipanema | B14: EDUARDO / JOSENILDO ANISIO | C14: KRK-3D12 | D14: 0.62847222 | E14: 0.68055556 | F14: 0.69791667 | H14: =MOD(F14-E14, 1) -> 0.017361111
... A17: Zona Sul Loja 12 - Leme | B17: HLOG / SILVIO | C17: UGA-1D55 | D17: 0.65277778 | E17: 0.6875 | F17: 0.73263889 | H17: =MOD(F17-E17, 1) -> 0.045138889
A18: Zona Sul Loja 38 - Copacabana | B18: RAPHAEL / LUIZ ALVES | C18: LCO-0978 | D18: não | E18: foi ao | F18: cliente | H18: 0
A19: Zona Sul Loja 40 - Ipanema | B19: LUCIANO / ANDERSON | C19: LVE-0688 | D19: 0.66319444 | E19: 0.70486111 | F19: 0.75694444 | H19: =MOD(F19-E19, 1) -> 0.052083333
A20: Zona Sul Loja 34 - Barra | B20: CARLOS GONÇALVES | C20: LNU-9595 | D20: SEM | E20: RASTREADOR | H20: 0
A21: Zona Sul Loja 35 - Barra | B21: ALEX | C21: LKW-2B80 | D21: 0.62847222 | E21: 0.65972222 | F21: 0.6875 | H21: =MOD(F21-E21, 1) -> 0.027777778
A22: Zona Sul Loja 43 - Barra (Península) | B22: SIDNEI / DIEGO | C22: KQB-3F31 | D22: SEM | E22: RASTREADOR | H22: 0
A23: Zona Sul Loja 34 - Barra | B23: SIDNEI / DIEGO | C23: KQB-3F31 | D23: SEM | E23: RASTREADOR | H23: 0
A24: Zona Sul Loja 47 - Catete | B24: HLOG / MARCOS | C24: TML-3B11 | D24: 0.66666667 | E24: 0.70486111 | F24: 0.72916667 | H24: =MOD(F24-E24, 1) -> 0.024305556
A25: Zona Sul Loja 45 - Flamengo | B25: MOBRICI | C25: AOP-3C73 | D25: 0.69097222 | E25: 0.71875 | F25: 0.77777778 | H25: =MOD(F25-E25, 1) -> 0.059027778
A26: Zona Sul Loja 19 - Copacabana | B26: SÉRGIO JOSE DA SILVA | C26: LJS-2172 | D26: 0.64583333 | E26: 0.6875 | F26: 0.76736111 | H26: =MOD(F26-E26, 1) -> 0.079861111
A27: Zona Sul Loja 05 - Copacabana III | B27: ALESSANDRA/ JONESON | C27: EBG-2D13 | D27: 0.68402778 | E27: 0.70833333 | F27: 0.75694444 | H27: =MOD(F27-E27, 1) -> 0.048611111
A28: Zona Sul Loja 20 - Botafogo | B28: ALESSANDRA/ JONESON | C28: EBG-2D13 | D28: 0.68402778 | E28: 0.77777778 | F28: 0.78819444 | H28: =MOD(F28-E28, 1) -> 0.010416667
A29: Zona Sul Loja 25 - Jd.Botânico | B29: DOUGLAS | C29: CZB-9J19 | D29: 0.6875 | E29: 0.72222222 | F29: 0.73958333 | H29: =MOD(F29-E29, 1) -> 0.017361111
A30: Zona Sul Loja 22 - S.Conrado | B30: DOUGLAS | C30: CZB-9J19 | D30: 0.6875 | E30: 0.74652778 | F30: 0.76041667 | H30: =MOD(F30-E30, 1) -> 0.013888889
A31: Zona Sul Loja 31 - Jd.Botânico | B31: FÁBIO BORGES | C31: LAF-0697 | D31: 0.65625 | E31: 0.6875 | F31: 0.69444444 | H31: =MOD(F31-E31, 1) -> 0.0069444444
A32: Zona Sul Loja 17 - Barra | B32: RENATO | C32: JAJ-6B36 | D32: 0.67708333 | E32: 0.71875 | F32: 0.73958333 | H32: =MOD(F32-E32, 1) -> 0.020833333
A33: Zona Sul Loja 23 - Barra | B33: LUIZ / CARLOS | C33: LUP-1F13 | D33: 0.62847222 | E33: 0.66319444 | F33: 0.70138889 | H33: =MOD(F33-E33, 1) -> 0.038194444
A34: Zona Sul Loja 44 - Barra | B34: LUIZ / CARLOS | C34: LUP-1F13 | D34: 0.62847222 | E34: 0.70486111 | F34: 0.71527778 | H34: =MOD(F34-E34, 1) -> 0.010416667
A35: Zona Sul Loja 10 - Recreio | B35: JHONATA FREIRE DA SILVA | C35: KYM-2I62 | D35: SEM | E35: RASTREADOR | H35: 0
A36: Zona Sul Mega Box 2 - Recreio | B36: EVERTON | C36: CYB-3B90 | D36: 0.66666667 | E36: 0.70138889 | F36: 0.72222222 | H36: =MOD(F36-E36, 1) -> 0.020833333
A37: Zona Sul Loja 03 - Copacabana I | B37: FÁBIO / RODRIGO | C37: KWK-4593 | D37: 0.68402778 | E37: 0.73263889 | F37: 0.74305556 | H37: =MOD(F37-E37, 1) -> 0.010416667
A38: Zona Sul Loja 26 - Copacabana | B38: FÁBIO / RODRIGO | C38: KWK-4593 | D38: 0.68402778 | E38: 0.74652778 | F38: 0.77083333 | H38: =MOD(F38-E38, 1) -> 0.024305556
A39: Zona Sul Loja 32 - Laranjeiras | B39: WILIAN FERES | C39: EFU-5704 | D39: 0.68055556 | E39: 0.70486111 | F39: 0.72916667 | H39: =MOD(F39-E39, 1) -> 0.024305556
A40: Zona Sul Loja 42 - Botafogo | B40: JOSUE DOS SANTOS | C40: BBH-1C94 | D40: 0.66666667 | E40: 0.71180556 | F40: 0.74652778 | H40: =MOD(F40-E40, 1) -> 0.034722222
A41: Zona Sul Mega Box 1 - Olaria | B41: FRANCISCO IRAN | C41: RJL-7D33 | D41: 0.62847222 | E41: 0.64930556 | F41: 0.66319444 | H41: =MOD(F41-E41, 1) -> 0.013888889
A42: Zona Sul Loja 1129 - Olaria | B42: SIDNEI / AGNALDO | C42: LKR-5990 | D42: 0.68055556 | E42: 0.69444444 | F42: 0.70833333 | H42: =MOD(F42-E42, 1) -> 0.013888889
...

Sheet 02
A1: RELATÓRIO KPI - Zona Sul BENASSI
A2: REDES / FILIAIS | B2: MOTORISTA | C2: PLACA | D2: SAIDA CD | E2: CHD LOJA 1 | F2: SAIDA LOJA 1 | H2: TEMPO EM LOJA 1
A3: Zona Sul Loja 11 - Leblon | B3: MARCIO / ERIVELTON | C3: KRH-5H67 | D3: NÃO | E3: FOI AO | F3: CLIENTE | H3: 0
A4: Zona Sul Loja 11 - Leblon | B4: WILLIAM | C4: INW-8A51 | D4: NÃO | E4: FOI AO | F4: CLIENTE | H4: 0
A5: Zona Sul Loja 11 - Leblon | B5: HLOG / BRUNO / MARTINS | C5: UBF-5G33 | D5: 0.21875 | E5: 0.25 | F5: 0.32986111 | H5: =MOD(F5-E5, 1) -> 0.079861111
A6: Zona Sul Loja 14 - Leblon | B6: JÚLIO COUTO/INACIO ARAUJO | C6: LQU-5546 | D6: 0.17013889 | E6: 0.20138889 | F6: 0.31597222 | H6: =MOD(F6-E6, 1) -> 0.11458333
A7: Zona Sul Loja 14 - Leblon | B7: JOSUE DOS SANTOS | C7: BBH-1C94 | D7: 0.21527778 | E7: 0.24652778 | F7: 0.34027778 | H7: =MOD(F7-E7, 1) -> 0.09375
A8: Zona Sul Loja 36 - Botafogo | B8: MOBRICI | C8: AOP-3C73 | D8: 0.22222222 | E8: 0.25 | F8: 0.29513889 | H8: =MOD(F8-E8, 1) -> 0.045138889
A9: Zona Sul Loja 33 - Humaitá | B9: MOBRICI | C9: AOP-3C73 | D9: 0.22222222 | E9: 0.30208333 | F9: 0.33333333 | H9: =MOD(F9-E9, 1) -> 0.03125
A10: Zona Sul Loja 30 - Laranjeiras | B10: SIDNEI ANTONIO MENDES | C10: LQE-5401 | D10: 0.19097222 | E10: 0.20833333 | F10: 0.22916667 | H10: =MOD(F10-E10, 1) -> 0.020833333
A11: Zona Sul Loja 21 - Flamengo | B11: FÁBIO / RODRIGO | C11: KWK-4593 | D11: 0.21527778 | E11: 0.23958333 | F11: 0.34375 | H11: =MOD(F11-E11, 1) -> 0.10416667
A12: Zona Sul Loja 04 - Copacabana II | B12: SANDRO EDUARDO/ MARCIO | C12: KVH-9J42 | D12: 0.20486111 | E12: 0.22569444 | F12: 0.35069444 | H12: =MOD(F12-E12, 1) -> 0.125
A13: Zona Sul Loja 18 - Copacabana | B13: ALEX | C13: LKW-2B80 | D13: 0.1875 | E13: 0.21875 | F13: 0.28125 | H13: =MOD(F13-E13, 1) -> 0.0625
A14: Zona Sul Loja 07 - Leblon | B14: RAPHAEL /LUIZ ALVES | C14: LCO-0978 | D14: 0.24652778 | E14: 0.34722222 | F14: 0.37847222 | H14: =MOD(F14-E14, 1) -> 0.03125
A15: Zona Sul Loja 07 - Leblon | B15: FÁBIO / VLADIMIR | C15: KQY-9E24 | D15: 0.21875 | E15: 0.25347222 | F15: 0.34375 | H15: =MOD(F15-E15, 1) -> 0.090277778
A16: Zona Sul Loja 48 - Recreio | B16: FRANCISCO IRAN | C16: RJL-7D33 | D16: 0.14930556 | E16: 0.17708333 | F16: 0.3125 | H16: =MOD(F16-E16, 1) -> 0.13541667
... A19: Zona Sul Loja 29 - Flamengo | B19: ALEX | C19: LKW-2B80 | D19: 0.66666667 | E19: 0.69444444 | F19: 0.71180556 | H19: =MOD(F19-E19, 1) -> 0.017361111
A20: Zona Sul Loja 11 - Leblon | B20: MARCIO / ERIVELTON | C20: KRH-5H67 | D20: NÃO | E20: FOI AO | F20: CLIENTE | H20: 0
A21: Zona Sul Loja 11 - Leblon | B21: WILLIAM / EDMILSON JOSÉ | C21: LTQ-0783 | D21: 0.48611111 | E21: 0.54513889 | F21: 0.61458333 | H21: =MOD(F21-E21, 1) -> 0.069444444
A22: Zona Sul Loja 08 - Ipanema | B22: DOUGLAS | C22: LTE-0A64 | D22: SEM | E22: RASTREADOR | H22: 0
A23: Zona Sul Loja 08 - Ipanema | B23: HLOG / MARCOS FERNANDO | C23: QSU-6I54 | D23: 0.73958333 | E23: 0.78125 | F23: 0.8125 | H23: =MOD(F23-E23, 1) -> 0.03125
A24: Zona Sul Loja 10 - Recreio | B24: CARLOS GONÇALVES | C24: LNU-9595 | D24: SEM | E24: RASTREADOR | H24: 0
A25: Zona Sul Loja 34 - Barra | B25: DOUGLAS | C25: CZB-9J19 | D25: 0.60069444 | E25: 0.63888889 | F25: 0.66319444 | H25: =MOD(F25-E25, 1) -> 0.024305556
A26: Zona Sul Loja 34 - Barra | B26: LUIZ / NILTON RODRIGUES | C26: AKZ-2594 | D26: 0.72222222 | E26: 0.75347222 | F26: 0.77777778 | H26: =MOD(F26-E26, 1) -> 0.024305556
A27: Zona Sul Loja 40 - Ipanema | B27: RAPHAEL / LUIZ ALVES | C27: LCO-0978 | D27: 0.65277778 | E27: 0.69444444 | F27: 0.76736111 | H27: =MOD(F27-E27, 1) -> 0.072916667
A28: Zona Sul Loja 40 - Ipanema | B28: HLOG / JONATHAN MARCIO | C28: TML-9I75 | D28: 0.77083333 | E28: 0.81597222 | F28: 0.86458333 | H28: =MOD(F28-E28, 1) -> 0.048611111
A29: Zona Sul Loja 45 - Flamengo | B29: MOBRICI | C29: AOP-3C73 | D29: 0.59375 | E29: 0.65972222 | F29: 0.69097222 | H29: =MOD(F29-E29, 1) -> 0.03125
A30: Zona Sul Loja 45 - Flamengo | B30: FELIPE SILVA | C30: KUL-1425 | D30: NÃO | E30: FOI AO | F30: CLIENTE | H30: 0
A31: Zona Sul Mega Box 1 - Olaria | B31: ALESSANDRA/ JONESON | C31: EBG-2D13 | D31: 0.64583333 | E31: 0.66319444 | F31: 0.69444444 | H31: =MOD(F31-E31, 1) -> 0.03125
A32: Zona Sul Mega Box 2 - Recreio | B32: JHONATA FREIRE DA SILVA | C32: KYM-2I62 | D32: SEM | E32: RASTREADOR | H32: 0
A33: Zona Sul Mega Box 1 - Olaria | B33: PAULO ROBERTO | C33: MDV-3746 | D33: SEM | E33: RASTREADOR | H33: 0
A34: Zona Sul Mega Box 2 - Recreio | B34: PAULO ROBERTO | C34: MDV-3746 | D34: SEM | E34: RASTREADOR | H34: 0
A35: Zona Sul Loja 01 - Ipanema | B35: FÁBIO / VLADIMIR | C35: KQY-9E24 | D35: 0.68055556 | E35: 0.72222222 | F35: 0.74652778 | H35: =MOD(F35-E35, 1) -> 0.024305556
A36: Zona Sul Loja 14 - Leblon | B36: JÚLIO COUTO / INACIO ARAUJO | C36: LQU-5546 | D36: 0.48958333 | E36: 0.53125 | H36: =MOD(F36-E36, 1) -> 0.46875
A37: Zona Sul Loja 09 - Ipanema | B37: FRANCISCO IRAN | C37: RJL-7D33 | D37: 0.625 | E37: 0.67708333 | F37: 0.71527778 | H37: =MOD(F37-E37, 1) -> 0.038194444
A38: Zona Sul Loja 43 - Barra (Península) | B38: SIDNEI / DIEGO | C38: KQB-3F31 | D38: SEM | E38: RASTREADOR | H38: 0
A39: Zona Sul Loja 35 - Barra | B39: SIDNEI / AGNALDO | C39: LKR-5990 | D39: 0.77777778 | E39: 0.86458333 | F39: 0.88541667 | H39: =MOD(F39-E39, 1) -> 0.020833333
A40: Zona Sul Loja 47 - Catete | B40: FÁBIO / RODRIGO | C40: KWK-4593 | D40: 0.69097222 | E40: 0.72222222 | F40: 0.76736111 | H40: =MOD(F40-E40, 1) -> 0.045138889
A41: Zona Sul Loja 20 - Botafogo | B41: EDUARDO / JOSENILDO ANISIO | C41: KRK-3D12 | D41: 0.79513889 | E41: 0.82986111 | F41: 0.89236111 | H41: =MOD(F41-E41, 1) -> 0.0625
A42: Zona Sul Loja 22 - S.Conrado | B42: WILIAN FERES | C42: EFU-5704 | D42: 0.84375 | E42: 0.88541667 | F42: 0.90277778 | H42: =MOD(F42-E42, 1) -> 0.017361111
...

Sheet 03
A1: RELATÓRIO KPI - Zona Sul BENASSI
A2: REDES / FILIAIS | B2: MOTORISTA | C2: PLACA | D2: SAIDA CD | E2: CHD LOJA 1 | F2: SAIDA LOJA 1 | H2: TEMPOI EM LOJA 1
A3: Zona Sul Loja 03 - Copacabana I | B3: MILTON | C3: KOP-4978 | D3: 0.25694444 | E3: 0.3125 | F3: 0.33333333 | H3: =MOD(F3-E3, 1) -> 0.020833333
A4: Zona Sul Loja 04 - Copacabana II | B4: SANDRO EDUARDO/ MARCIO | C4: KVH-9J42 | D4: 0.28819444 | E4: 0.31944444 | F4: 0.36111111 | H4: =MOD(F4-E4, 1) -> 0.041666667
A5: Zona Sul Loja 05 - Copacabana III | B5: FÁBIO P. /RODRIGO | C5: KWK-4593 | D5: 0.23263889 | E5: 0.28125 | F5: 0.30555556 | H5: =MOD(F5-E5, 1) -> 0.024305556
A6: Zona Sul Loja 38 - Copacabana | B6: FÁBIO P. /RODRIGO | C6: KWK-4593 | D6: 0.23263889 | E6: 0.3125 | F6: 0.35763889 | H6: =MOD(F6-E6, 1) -> 0.045138889
A7: Zona Sul Loja 12 - Leme | B7: JÚLIO COUTO / INACIO ARAUJO | C7: LQU-5546 | D7: 0.19097222 | E7: 0.22569444 | F7: 0.38194444 | H7: =MOD(F7-E7, 1) -> 0.15625
A8: Zona Sul Loja 18 - Copacabana | B8: ALEX | C8: LKW-2B80 | D8: 0.22569444 | E8: 0.25694444 | F8: 0.30555556 | H8: =MOD(F8-E8, 1) -> 0.048611111
A9: Zona Sul Loja 19 - Copacabana | B9: JOSUE DOS SANTOS | C9: BBH-1C94 | D9: 0.39930556 | E9: 0.43055556 | F9: 0.52430556 | H9: =MOD(F9-E9, 1) -> 0.09375
A10: Zona Sul Loja 26 - Copacabana | B10: FÁBIO / VLADIMIR | C10: KQY-9E24 | D10: 0.23611111 | E10: 0.26736111 | F10: 0.29861111 | H10: =MOD(F10-E10, 1) -> 0.03125
A11: Zona Sul Loja 30 - Laranjeiras | B11: SIDNEI ANTONIO MENDES | C11: LQE-5401 | D11: 0.20138889 | E11: 0.22569444 | F11: 0.29166667 | H11: =MOD(F11-E11, 1) -> 0.065972222
A12: Zona Sul Loja 21 - Flamengo | B12: MOBRICE | C12: AOP-3C73 | D12: 0.24652778 | E12: 0.3125 | F12: 0.33680556 | H12: =MOD(F12-E12, 1) -> 0.024305556
A13: Zona Sul Loja 33 - Humaitá | B13: MOBRICE | C13: AOP-3C73 | D13: 0.24652778 | E13: 0.34027778 | F13: 0.36111111 | H13: =MOD(F13-E13, 1) -> 0.020833333
A14: Zona Sul Loja 36 - Botafogo | B14: RAPHAEL / LUIZ ALVES | C14: LCO-0978 | D14: 0.22569444 | E14: 0.25347222 | F14: 0.33680556 | H14: =MOD(F14-E14, 1) -> 0.083333333
... A16: Zona Sul Loja 13 - Angra | B16: JULIO | C16: CZB-9J19 | D16: 0 | E16: 0.27083333 | F16: 0.30555556 | H16: =MOD(F16-E16, 1) -> 0.034722222
H17: =MOD(F17-E17, 1) -> 0
H18: =MOD(F18-E18, 1) -> 0
H19: =MOD(F19-E19, 1) -> 0
H20: =MOD(F20-E20, 1) -> 0
H21: =MOD(F21-E21, 1) -> 0
H22: =MOD(F22-E22, 1) -> 0
H23: =MOD(F23-E23, 1) -> 0
H24: =MOD(F24-E24, 1) -> 0
H25: =MOD(F25-E25, 1) -> 0
H26: =MOD(F26-E26, 1) -> 0
H27: =MOD(F27-E27, 1) -> 0
H28: =MOD(F28-E28, 1) -> 0
... H68: =MOD(F68-E68, 1) -> 0

Sheet 04
A1: RELATÓRIO KPI - Zona Sul BENASSI
A2: REDES / FILIAIS | B2: MOTORISTA | C2: PLACA | D2: SAIDA CD | E2: CHD LOJA 1 | F2: SAIDA LOJA 1 | H2: TEMPOI EM LOJA 1
A3: Zona Sul Loja 19 - Copacabana | B3: SÉRGIO JOSE DA SILVA | C3: LJS-2172 | D3: NÃO | E3: FOI AO | F3: CLIENTE | H3: 0
A4: Zona Sul Loja 26 - Copacabana | B4: FÁBIO / VLADIMIR | C4: KQY-9E24 | D4: NÃO | E4: FOI AO | F4: CLIENTE | H4: 0
A5: Zona Sul Loja 30 - Laranjeiras | B5: SIDNEI ANTONIO MENDES | C5: LQE-5401 | D5: NÃO | E5: FOI AO | F5: CLIENTE | H5: 0
A6: Zona Sul Loja 36 - Botafogo | B6: RAPHAEL / LUIZ ALVES | C6: LCO-0978 | D6: 0.22222222 | E6: 0.25 | F6: 0.29513889 | H6: =MOD(F6-E6, 1) -> 0.045138889
A7: Zona Sul Loja 48 - Recreio | B7: FRANCISCO IRAN | C7: RJL-7D33 | D7: NÃO | E7: FOI AO | F7: CLIENTE | H7: 0
A8: Zona Sul Loja 13 - Angra | B8: JULIO | C8: CZB-9J19 | D8: NÃO | E8: FOI AO | F8: CLIENTE | H8: 0
A9: Zona Sul Loja 27 - Ipanema | B9: MOBRICI | C9: AOP-3C73 | D9: 0.17708333 | E9: 0.22222222 | F9: 0.23263889 | H9: =MOD(F9-E9, 1) -> 0.010416667
A10: Zona Sul Loja 15 - Leblon | B10: MOBRICI | C10: AOP-3C73 | D10: 0.17708333 | E10: 0.24305556 | F10: 0.28125 | H10: =MOD(F10-E10, 1) -> 0.038194444
A11: Zona Sul Loja 07 - Leblon | B11: RAPHAEL /LUIZ ALVES | C11: LCO-0978 | D11: NÃO | E11: FOI AO | F11: CLIENTE | H11: 0
A12: Zona Sul Loja 04 - Copacabana II | B12: MILTON | C12: KOP-4978 | D12: 0.50694444 | E12: 0.55208333 | F12: 0.56597222 | H12: =MOD(F12-E12, 1) -> 0.013888889
A13: Zona Sul Loja 18 - Copacabana | B13: MILTON | C13: KOP-4978 | D13: 0.50694444 | E13: 0.56944444 | F13: 0.63194444 | H13: =MOD(F13-E13, 1) -> 0.0625
A14: Zona Sul Loja 15 - Leblon | B14: ALEX | C14: LKW-2B80 | D14: 0.48958333 | E14: 0.56597222 | F14: 0.57986111 | H14: =MOD(F14-E14, 1) -> 0.013888889
A15: Zona Sul Loja 25 - Jd.Botânico | B15: ALEX | C15: LKW-2B80 | D15: 0.48958333 | E15: 0.53819444 | F15: 0.55902778 | H15: =MOD(F15-E15, 1) -> 0.020833333
A16: Zona Sul Loja 46 - Botafogo | B16: FÁBIO / VLADIMIR | C16: KQY-9E24 | D16: 0.48611111 | E16: 0.53472222 | F16: 0.57291667 | H16: =MOD(F16-E16, 1) -> 0.038194444
A17: Zona Sul Loja 36 - Botafogo | B17: FÁBIO / VLADIMIR | C17: KQY-9E24 | D17: 0.48611111 | E17: 0.57638889 | F17: 0.59027778 | H17: =MOD(F17-E17, 1) -> 0.013888889
A18: Zona Sul Loja 47 - Catete | B18: FRANCISCO IRAN | C18: RJL-7D33 | D18: 0.45833333 | E18: 0.49305556 | F18: 0.52777778 | H18: =MOD(F18-E18, 1) -> 0.034722222
A19: Zona Sul Loja 31 - Jd.Botânico | B19: FRANCISCO IRAN | C19: RJL-7D33 | D19: 0.45833333 | E19: 0.55208333 | F19: 0.5625 | H19: =MOD(F19-E19, 1) -> 0.010416667
A20: Zona Sul Loja 10 - Recreio | B20: FÁBIO P. /RODRIGO | C20: KWK-4593 | D20: 0.47569444 | E20: 0.59722222 | F20: 0.61111111 | H20: =MOD(F20-E20, 1) -> 0.013888889
A21: Zona Sul Loja 17 - Barra | B21: FÁBIO P. /RODRIGO | C21: KWK-4593 | D21: 0.47569444 | E21: 0.51041667 | F21: 0.58333333 | H21: =MOD(F21-E21, 1) -> 0.072916667
A22: Zona Sul Loja 1129 - Olaria | B22: SIDNEI /DIEGO | C22: KQB-3F31 | D22: SEM | E22: RASTREADOR | H22: 0
A23: Zona Sul Mega Box 1 - Olaria | B23: SIDNEI /DIEGO | C23: KQB-3F31 | D23: SEM | E23: RASTREADOR | H23: 0
A24: Zona Sul Loja 08 - Ipanema | B24: SÉRGIO JOSE DA SILVA* | C24: LJS-2172 | D24: 0.45138889 | E24: 0.50694444 | F24: 0.63194444 | H24: =MOD(F24-E24, 1) -> 0.125
A25: Zona Sul Loja 19 - Copacabana | B25: LUIZ / NILTON RODRIGUES | C25: AKZ-2594 | D25: 0.45833333 | E25: 0.5 | F25: 0.58680556 | H25: =MOD(F25-E25, 1) -> 0.086805556
A26: Zona Sul Mega Box 2 - Recreio | B26: ALESSANDRA/ JONESON | C26: EBG-2D13 | D26: 0.67361111 | E26: 0.70833333 | F26: 0.75347222 | H26: =MOD(F26-E26, 1) -> 0.045138889
A27: Zona Sul Loja 34 - Barra | B27: THIAGO | C27: CYB-3B90 | D27: 0.46875 | E27: 0.51041667 | F27: 0.53125 | H27: =MOD(F27-E27, 1) -> 0.020833333
A28: Zona Sul Loja 28 - Urca | B28: EDUARDO / JOSENILDO ANISIO | C28: KRK-3D12 | D28: 0.64930556 | E28: 0.6875 | F28: 0.70833333 | H28: =MOD(F28-E28, 1) -> 0.020833333
A29: Zona Sul Loja 29 - Flamengo | B29: EDUARDO / JOSENILDO ANISIO | C29: KRK-3D12 | D29: 0.64930556 | E29: 0.71875 | F29: 0.73958333 | H29: =MOD(F29-E29, 1) -> 0.020833333
A30: Zona Sul Loja 07 - Leblon | B30: ALESSIO | C30: KQR-2J11 | D30: 0.63888889 | E30: 0.67013889 | F30: 0.69444444 | H30: =MOD(F30-E30, 1) -> 0.024305556
A31: Zona Sul Loja 11 - Leblon | B31: MARCIO / ERIVELTON | C31: KRH-5H67 | D31: 0.69444444 | E31: 0.77777778 | F31: 0.79861111 | H31: =MOD(F31-E31, 1) -> 0.020833333
A32: Zona Sul Loja 11 - Leblon | B32: HLOG / DENIS/FABIO | C32: UBF-5G33 | D32: 0.57986111 | E32: 0.61111111 | F32: 0.73611111 | H32: =MOD(F32-E32, 1) -> 0.125
A33: Zona Sul Loja 11 - Leblon | B33: WILLIAM | C33: INW-8A51 | D33: 0.5625 | E33: 0.60763889 | F33: 0.69444444 | H33: =MOD(F33-E33, 1) -> 0.086805556
A34: Zona Sul Loja 08 - Ipanema | B34: DOUGLAS | C34: CZB-9J19 | D34: 0.66319444 | E34: 0.70833333 | F34: 0.71527778 | H34: =MOD(F34-E34, 1) -> 0.0069444444
A35: Zona Sul Loja 09 - Ipanema | B35: TIAGO DA COSTA | C35: TTX-9E34 | D35: SEM | E35: RASTREADOR | H35: 0
A36: Zona Sul Loja 01 - Ipanema | B36: JHONATA FREIRE DA SILVA | C36: KYM-2I62 | D36: SEM | E36: RASTREADOR | H36: 0
A37: Zona Sul Loja 12 - Leme | B37: DOUGLAS | C37: LTE-0A64 | D37: SEM | E37: RASTREADOR | H37: 0
A38: Zona Sul Loja 38 - Copacabana | B38: LUCIANO / ANDERSON | C38: LVE-0688 | D38: 0.69097222 | E38: 0.73958333 | F38: 0.76736111 | H38: =MOD(F38-E38, 1) -> 0.027777778
A39: Zona Sul Loja 14 - Leblon | B39: MOBRICI | C39: AOP-3C73 | D39: 0.63888889 | E39: 0.76388889 | F39: 0.85763889 | H39: =MOD(F39-E39, 1) -> 0.09375
A40: Zona Sul Loja 43 - Barra (Península) | B40: RAPHAEL / LUIZ ALVES | C40: LCO-0978 | D40: 0.61805556 | E40: 0.65277778 | F40: 0.70833333 | H40: =MOD(F40-E40, 1) -> 0.055555556
...

Sheet 05
A1: RELATÓRIO KPI - Zona Sul BENASSI
A2: REDES / FILIAIS | B2: MOTORISTA | C2: PLACA | D2: SAIDA CD | E2: CHD LOJA 1 | F2: SAIDA LOJA 1 | H2: TEMPO EM LOJA 1
A3: Zona Sul Loja 33 - Humaitá | B3: SANDRO EDUARDO / MARCIO | C3: KVH-9J42 | D3: 0.20138889 | E3: 0.22222222 | F3: 0.30902778 | H3: =MOD(F3-E3, 1) -> 0.086805556
A4: Zona Sul Loja 21 - Flamengo | B4: FÁBIO P. /RODRIGO | C4: KWK-4593 | D4: 0.20138889 | E4: 0.22569444 | F4: 0.29513889 | H4: =MOD(F4-E4, 1) -> 0.069444444
A5: Zona Sul Loja 30 - Laranjeiras | B5: SIDNEI ANTONIO MENDES | C5: LQE-5401 | D5: 0.18402778 | E5: 0.20486111 | F5: 0.27777778 | H5: =MOD(F5-E5, 1) -> 0.072916667
A6: Zona Sul Loja 27 - Ipanema | B6: MOBRICI | C6: AOP-3C73 | D6: 0.18402778 | E6: 0.21180556 | F6: 0.22569444 | H6: =MOD(F6-E6, 1) -> 0.013888889
A7: Zona Sul Loja 15 - Leblon | B7: MOBRICI | C7: AOP-3C73 | D7: 0.18402778 | E7: 0.22916667 | F7: 0.28125 | H7: =MOD(F7-E7, 1) -> 0.052083333
A8: Zona Sul Loja 04 - Copacabana II | B8: JOSUE DOS SANTOS | C8: BBH-1C94 | D8: 0.19097222 | E8: 0.21875 | F8: 0.30208333 | H8: =MOD(F8-E8, 1) -> 0.083333333
A9: Zona Sul Loja 18 - Copacabana | B9: JOSUE DOS SANTOS | C9: BBH-1C94 | D9: 0.19097222 | E9: 0.30555556 | F9: 0.31597222 | H9: =MOD(F9-E9, 1) -> 0.010416667
A10: Zona Sul Loja 07 - Leblon | B10: RAPHAEL /LUIZ ALVES | C10: LCO-0978 | D10: 0.25694444 | E10: 0.31944444 | F10: 0.48958333 | H10: =MOD(F10-E10, 1) -> 0.17013889
A11: Zona Sul Loja 48 - Recreio | B11: FRANCISCO IRAN | C11: RJL-7D33 | D11: 0.14583333 | E11: 0.18055556 | F11: 0.28819444 | H11: =MOD(F11-E11, 1) -> 0.10763889
A12: Zona Sul Loja 13 - Angra | B12: JULIO | C12: CZB-9J19 | D12: 0 | E12: 0.27083333 | F12: 0.30555556 | H12: =MOD(F12-E12, 1) -> 0.034722222
A13: Zona Sul Loja 28 - Urca | B13: FÁBIO / VLADIMIR | C13: KQY-9E24 | D13: 0.61805556 | E13: 0.65625 | F13: 0.66666667 | H13: =MOD(F13-E13, 1) -> 0.010416667
A14: Zona Sul Loja 29 - Flamengo | B14: FÁBIO / VLADIMIR | C14: KQY-9E24 | D14: 0.61805556 | E14: 0.67708333 | F14: 0.69791667 | H14: =MOD(F14-E14, 1) -> 0.020833333
... A28: Zona Sul Loja 47 - Catete | B28: FRANCISCO IRAN | C28: RJL-7D33 | D28: 0.73611111 | E28: 0.77430556 | F28: 0.80902778 | H28: =MOD(F28-E28, 1) -> 0.034722222
A29: Zona Sul Loja 45 - Flamengo | B29: CARLOS GONÇALVES | C29: LNU-9595 | D29: SEM | E29: RASTREADOR | H29: =MOD(F29-E29, 1) -> #VALUE!
A30: Zona Sul Loja 19 - Copacabana | B30: TIAGO DA COSTA | C30: TTX-9E34 | D30: SEM | E30: RASTREADOR | H30: =MOD(F30-E30, 1) -> #VALUE!
A31: Zona Sul Loja 26 - Copacabana | B31: SIDNEI / AGNALDO | C31: LKR-5990 | D31: 0.78819444 | E31: 0.84375 | F31: 0.85069444 | H31: =MOD(F31-E31, 1) -> 0.0069444444
A32: Zona Sul Loja 25 - Jd.Botânico | B32: LUCIANO / ANDERSON | C32: LVE-0688 | D32: 0.67708333 | E32: 0.88541667 | F32: 0.89930556 | H32: =MOD(F32-E32, 1) -> 0.013888889
A33: Zona Sul Loja 22 - S.Conrado | B33: LUCIANO / ANDERSON | C33: LVE-0688 | D33: 0.67708333 | E33: 0.90625 | F33: 0.91666667 | H33: =MOD(F33-E33, 1) -> 0.010416667
A34: Zona Sul Loja 31 - Jd.Botânico | B34: SIDNEI ANTONIO | C34: LQE-5401 | D34: 0.82638889 | E34: 0.875 | F34: 0.89583333 | H34: =MOD(F34-E34, 1) -> 0.020833333
A35: Zona Sul Loja 17 - Barra | B35: PAULO ROBERTO | C35: MDV-3746 | D35: SEM | E35: RASTREADOR | H35: =MOD(F35-E35, 1) -> #VALUE!
A36: Zona Sul Loja 23 - Barra | B36: SIDNEI / DIEGO | C36: KQB-3F31 | D36: SEM | E36: RASTREADOR | H36: =MOD(F36-E36, 1) -> #VALUE!
A37: Zona Sul Loja 44 - Barra | B37: SIDNEI / DIEGO | C37: KQB-3F31 | D37: SEM | E37: RASTREADOR | H37: =MOD(F37-E37, 1) -> #VALUE!
A38: Zona Sul Loja 10 - Recreio | B38: RAPHAEL / LUIZ ALVES (1º CARRO) | C38: LCO-0978 | D38: 0.74305556 | E38: 0.79166667 | F38: 0.81944444 | H38: =MOD(F38-E38, 1) -> 0.027777778
A39: Zona Sul Mega Box 2 - Recreio | B39: ANTONIO | C39: MES7F27 | D39: 0.80555556 | E39: 0.84722222 | F39: 0.85763889 | H39: =MOD(F39-E39, 1) -> 0.010416667
A40: Zona Sul Loja 10 - Recreio | B40: MILTON (2º carro fl. 10 e MEGA BOX 2) | C40: KOP-4978 | D40: 0.78125 | E40: 0.84027778 | F40: 0.85069444 | H40: =MOD(F40-E40, 1) -> 0.010416667
A41: Zona Sul Mega Box 2 - Recreio | B41: MILTON (2º carro fl. 10 e MEGA BOX 2) | C41: KOP-4978 | D41: 0.78125 | E41: 0.82291667 | F41: 0.83680556 | H41: =MOD(F41-E41, 1) -> 0.013888889
A42: Zona Sul Loja 40 - Ipanema | B42: DOUGLAS | C42: LTE-0A64 | D42: SEM | E42: RASTREADOR | H42: =MOD(F42-E42, 1) -> #VALUE!
A43: Zona Sul Loja 03 - Copacabana I | B43: FELIPE SILVA | C43: KUL-1425 | D43: NÃO | E43: FOI AO | F43: CLIENTE | H43: =MOD(F43-E43, 1) -> #VALUE!
A44: Zona Sul Loja 05 - Copacabana III | B44: FELIPE SILVA | C44: KUL-1425 | D44: NÃO | E44: FOI AO | F44: CLIENTE | H44: =MOD(F44-E44, 1) -> #VALUE!
A45: Zona Sul Loja 32 - Laranjeiras | B45: FÁBIO BORGES | C45: LAF-0697 | D45: NÃO | E45: FOI AO | F45: CLIENTE | H45: =MOD(F45-E45, 1) -> #VALUE!
A46: Zona Sul Loja 20 - Botafogo | B46: WILIAN FERES | C46: EFU-5704 | D46: 0.82638889 | E46: 0.85416667 | F46: 0.89236111 | H46: =MOD(F46-E46, 1) -> 0.038194444
A47: Zona Sul Loja 42 - Botafogo | B47: LUIZ | C47: AKZ-2594 | D47: 0.82291667 | E47: 0.86111111 | F47: 0.89236111 | H47: =MOD(F47-E47, 1) -> 0.03125
A48: Zona Sul Loja 06 - Gávea | B48: JOSUE DOS SANTOS | C48: BBH-1C94 | D48: 0.8125 | E48: 0.86111111 | F48: 0.91319444 | H48: =MOD(F48-E48, 1) -> 0.052083333
A49: Zona Sul Mega Box 1 - Olaria | B49: JULIO | C49: KNC5J75 | D49: 0.79166667 | E49: 0.80208333 | F49: 0.84027778 | H49: =MOD(F49-E49, 1) -> 0.038194444
A50: Zona Sul Loja 1129 - Olaria | B50: SERGIO | C50: LJS2172 | D50: 0.8125 | E50: 0.84722222 | F50: 0.85763889 | H50: =MOD(F50-E50, 1) -> 0.010416667
A51: Zona Sul Loja 46 - Botafogo | B51: RENATO | C51: JAJ-6B36 | D51: 0.8125 | E51: 0.86111111 | F51: 0.87847222 | H51: =MOD(F51-E51, 1) -> 0.017361111
H52: =MOD(F52-E52, 1) -> 0
H53: =MOD(F53-E53, 1) -> 0
...

Sheet 06
A1: RELATÓRIO KPI - Zona Sul BENASSI
A2: REDES / FILIAIS | B2: MOTORISTA | C2: PLACA | D2: SAIDA CD | E2: CHD LOJA 1 | F2: SAIDA LOJA 1 | H2: TEMPO EM LOJA 1
A3: Zona Sul Loja 36 - Botafogo | B3: JOSUE DOS SANTOS | C3: BBH-1C94 | D3: 0.19444444 | E3: 0.21875 | F3: 0.30555556 | H3: =MOD(F3-E3, 1) -> 0.086805556
A4: Zona Sul Loja 33 - Humaitá | B4: JÚLIO COUTO/INACIO ARAUJO | C4: LQU-5546 | D4: 0.15972222 | E4: 0.1875 | F4: 0.30902778 | H4: =MOD(F4-E4, 1) -> 0.12152778
A5: Zona Sul Loja 30 - Laranjeiras | B5: SIDNEI ANTONIO MENDES | C5: LQE-5401 | D5: 0.20138889 | E5: 0.22222222 | F5: 0.23611111 | H5: =MOD(F5-E5, 1) -> 0.013888889
A6: Zona Sul Loja 21 - Flamengo | B6: FÁBIO / LUIZ ALBERTO | C6: KQY-9E24 | D6: 0.20486111 | E6: 0.22569444 | F6: 0.32291667 | H6: =MOD(F6-E6, 1) -> 0.097222222
A7: Zona Sul Loja 04 - Copacabana II | B7: SANDRO EDUARDO/ MARCIO | C7: KVH-9J42 | D7: 0.20833333 | E7: 0.25 | F7: 0.32986111 | H7: =MOD(F7-E7, 1) -> 0.079861111
A8: Zona Sul Loja 18 - Copacabana | B8: ALEX | C8: LKW-2B80 | D8: 0.19444444 | E8: 0.22222222 | F8: 0.28472222 | H8: =MOD(F8-E8, 1) -> 0.0625
A9: Zona Sul Loja 27 - Ipanema | B9: MOBRICI | C9: AOP-3C73 | D9: 0.20486111 | E9: 0.25347222 | F9: 0.27083333 | H9: =MOD(F9-E9, 1) -> 0.017361111
A10: Zona Sul Loja 15 - Leblon | B10: MOBRICI | C10: AOP-3C73 | D10: 0.20486111 | E10: 0.27430556 | F10: 0.28819444 | H10: =MOD(F10-E10, 1) -> 0.013888889
A11: Zona Sul Loja 07 - Leblon | B11: RAPHAEL / LUIZ ALVES | C11: LCO-0978 | D11: 0.25347222 | E11: 0.31597222 | F11: 0.42361111 | H11: =MOD(F11-E11, 1) -> 0.10763889
A12: Zona Sul Loja 48 - Recreio | B12: FRANCISCO IRAN | C12: RJL-7D33 | D12: 0.14930556 | E12: 0.18055556 | F12: 0.29513889 | H12: =MOD(F12-E12, 1) -> 0.11458333
A13: Zona Sul Loja 13 - Angra | B13: JULIO | C13: CZB-9J19 | D13: 0.13194444 | E13: 0.26041667 | F13: 0.30208333 | H13: =MOD(F13-E13, 1) -> 0.041666667
A14: Zona Sul Loja 28 - Urca | B14: WILLIAM / EDMILSON JOSÉ | C14: LTQ-0783 | D14: 0.61111111 | E14: 0.65277778 | F14: 0.67361111 | H14: =MOD(F14-E14, 1) -> 0.020833333
... A27: Zona Sul Loja 35 - Barra | B27: FÁBIO / RODRIGO (2º CARRO FL. 34) | C27: KWK-4593 | D27: 0.67361111 | E27: 0.72569444 | F27: 0.74652778 | H27: =MOD(F27-E27, 1) -> 0.020833333
A28: Zona Sul Loja 34 - Barra | B28: FÁBIO / RODRIGO (2º CARRO FL. 34) | C28: KWK-4593 | D28: NÃO | E28: FOI AO | F28: CLIENTE | H28: 0
A29: Zona Sul Loja 43 - Barra (Península) | B29: RAPHAEL / LUIZ ALVES | C29: LCO-0978 | D29: 0.625 | E29: 0.65972222 | F29: 0.70138889 | H29: =MOD(F29-E29, 1) -> 0.041666667
A30: Zona Sul Loja 47 - Catete | B30: FÁBIO / VLADIMIR | C30: KQY-9E24 | D30: 0.63888889 | E30: 0.68055556 | F30: 0.73263889 | H30: =MOD(F30-E30, 1) -> 0.052083333
A31: Zona Sul Loja 45 - Flamengo | B31: DOUGLAS | C31: LTE-0A64 | D31: SEM | E31: RASTREADOR | H31: 0
A32: Zona Sul Loja 19 - Copacabana | B32: MOBRICI | C32: AOP-3C73 | D32: 0.66319444 | E32: 0.69791667 | F32: 0.74305556 | H32: =MOD(F32-E32, 1) -> 0.045138889
A33: Zona Sul Loja 26 - Copacabana | B33: MILTON | C33: KOP-4978 | D33: 0.72916667 | E33: 0.77777778 | F33: 0.8125 | H33: =MOD(F33-E33, 1) -> 0.034722222
A34: Zona Sul Loja 06 - Gávea | B34: RENATO | C34: JAJ-6B36 | D34: 0.75347222 | E34: 0.82291667 | F34: 0.84027778 | H34: =MOD(F34-E34, 1) -> 0.017361111
A35: Zona Sul Loja 22 - S.Conrado | B35: RENATO | C35: JAJ-6B36 | D35: 0.75347222 | E35: 0.84722222 | F35: 0.85763889 | H35: =MOD(F35-E35, 1) -> 0.010416667
A36: Zona Sul Loja 31 - Jd.Botânico | B36: LUIZ / NILTON RODRIGUES | C36: AKZ-2594 | D36: 0.72916667 | E36: 0.83333333 | F36: 0.85763889 | H36: =MOD(F36-E36, 1) -> 0.024305556
A37: Zona Sul Loja 25 - Jd.Botânico | B37: LUIZ / NILTON RODRIGUES | C37: AKZ-2594 | D37: 0.72916667 | E37: 0.79166667 | F37: 0.82638889 | H37: =MOD(F37-E37, 1) -> 0.034722222
A38: Zona Sul Loja 17 - Barra | B38: MARCIO | C38: LTH-4J15 | D38: 0.78472222 | E38: 0.81944444 | F38: 0.85763889 | H38: =MOD(F38-E38, 1) -> 0.038194444
A39: Zona Sul Loja 23 - Barra | B39: EDUARDO / JOSENILDO ANISIO | C39: KRK-3D12 | D39: 0.72916667 | E39: 0.77430556 | F39: 0.80555556 | H39: =MOD(F39-E39, 1) -> 0.03125
A40: Zona Sul Loja 44 - Barra | B40: EDUARDO / JOSENILDO ANISIO | C40: KRK-3D12 | D40: 0.72916667 | E40: 0.8125 | F40: 0.83333333 | H40: =MOD(F40-E40, 1) -> 0.020833333
A41: Zona Sul Loja 10 - Recreio | B41: SIDNEI / DIEGO | C41: KQB-3F31 | D41: 0.77083333 | E41: 0.81944444 | F41: 0.86111111 | H41: =MOD(F41-E41, 1) -> 0.041666667
A42: Zona Sul Mega Box 2 - Recreio | B42: PAULO | C42: LNU7H38 | D42: 0.72916667 | E42: 0.8125 | F42: 0.82291667 | H42: =MOD(F42-E42, 1) -> 0.010416667
A43: Zona Sul Loja 40 - Ipanema | B43: SÉRGIO JOSE DA SILVA | C43: LJS-2172 | D43: NÃO | E43: FOI AO | F43: CLIENTE | H43: 0
A44: Zona Sul Loja 03 - Copacabana I | B44: SIDNEI / AGNALDO | C44: LKR-5990 | D44: SEM | E44: RASTREADOR | H44: 0
A45: Zona Sul Loja 05 - Copacabana III | B45: SIDNEI / AGNALDO | C45: LKR-5990 | D45: SEM | E45: RASTREADOR | H45: 0
A46: Zona Sul Loja 32 - Laranjeiras | B46: LUCIANO / ANDERSON | C46: LVE-0688 | D46: 0.72569444 | E46: 0.80902778 | F46: 0.83680556 | H46: =MOD(F46-E46, 1) -> 0.027777778
A47: Zona Sul Loja 42 - Botafogo | B47: LUCIANO / ANDERSON | C47: LVE-0688 | D47: 0.72569444 | E47: 0.77777778 | F47: 0.79513889 | H47: =MOD(F47-E47, 1) -> 0.017361111
A48: Zona Sul Loja 20 - Botafogo | B48: FÁBIO BORGES | C48: LAF-0697 | D48: 0.74305556 | E48: 0.77083333 | F48: 0.79861111 | H48: =MOD(F48-E48, 1) -> 0.027777778
A49: Zona Sul Mega Box 1 - Olaria | B49: EDUARDO | C49: LQA-5883 | D49: SEM | E49: RASTREADOR | H49: 0
A50: Zona Sul Loja 1129 - Olaria | B50: EDUARDO | C50: LQA-5883 | D50: SEM | E50: RASTREADOR | H50: 0
A51: Zona Sul Loja 46 - Botafogo | B51: EVERTON | C51: CYB-3B90 | D51: 0.76736111 | E51: 0.82291667 | F51: 0.84375 | H51: =MOD(F51-E51, 1) -> 0.020833333
H52: =MOD(F52-E52, 1) -> 0
...

Sheet 07
A1: RELATÓRIO KPI - Zona Sul BENASSI
A2: REDES / FILIAIS | B2: MOTORISTA | C2: PLACA | D2: SAIDA CD | E2: CHD LOJA 1 | F2: SAIDA LOJA 1 | H2: TEMPO EM LOJA 1
A3: Zona Sul Loja 36 - Botafogo | B3: JOSUE DOS SANTOS | C3: BBH-1C94 | D3: 0.18402778 | E3: 0.20833333 | F3: 0.29861111 | H3: =MOD(F3-E3, 1) -> 0.090277778
A4: Zona Sul Loja 33 - Humaitá | B4: JÚLIO COUTO/INACIO ARAUJO | C4: LQU-5546 | D4: 0.15277778 | E4: 0.18402778 | F4: 0.30555556 | H4: =MOD(F4-E4, 1) -> 0.12152778
A5: Zona Sul Loja 30 - Laranjeiras | B5: SIDNEI ANTONIO MENDES | C5: LQE-5401 | D5: 0.20138889 | E5: 0.22916667 | F5: 0.24305556 | H5: =MOD(F5-E5, 1) -> 0.013888889
A6: Zona Sul Loja 21 - Flamengo | B6: FÁBIO / LUIZ ALBERTO | C6: KQY-9E24 | D6: 0.21527778 | E6: 0.24652778 | F6: 0.30902778 | H6: =MOD(F6-E6, 1) -> 0.0625
A7: Zona Sul Loja 04 - Copacabana II | B7: SANDRO EDUARDO/ MARCIO | C7: KVH-9J42 | D7: 0.20486111 | E7: 0.24652778 | F7: 0.36111111 | H7: =MOD(F7-E7, 1) -> 0.11458333
A8: Zona Sul Loja 18 - Copacabana | B8: ALEX | C8: LKW-2B80 | D8: 0.1875 | E8: 0.21527778 | F8: 0.28125 | H8: =MOD(F8-E8, 1) -> 0.065972222
A9: Zona Sul Loja 27 - Ipanema | B9: FÁBIO / RODRIGO | C9: KWK-4593 | D9: 0.19791667 | E9: 0.22916667 | F9: 0.23958333 | H9: =MOD(F9-E9, 1) -> 0.010416667
A10: Zona Sul Loja 15 - Leblon | B10: FÁBIO / RODRIGO | C10: KWK-4593 | D10: 0.19791667 | E10: 0.24305556 | F10: 0.25694444 | H10: =MOD(F10-E10, 1) -> 0.013888889
A11: Zona Sul Loja 07 - Leblon | B11: RAPHAEL / LUIZ ALVES | C11: LCO-0978 | D11: 0.23958333 | E11: 0.29166667 | F11: 0.44097222 | H11: =MOD(F11-E11, 1) -> 0.14930556
A12: Zona Sul Loja 48 - Recreio | B12: FRANCISCO IRAN | C12: RJL-7D33 | D12: 0.14583333 | E12: 0.17708333 | F12: 0.29166667 | H12: =MOD(F12-E12, 1) -> 0.11458333
A13: Zona Sul Loja 13 - Angra | B13: JULIO | C13: CZB-9J19 | D13: 0.13541667 | E13: 0.26388889 | F13: 0.3125 | H13: =MOD(F13-E13, 1) -> 0.048611111
A14: Zona Sul Loja 28 - Urca | B14: WILLIAM / EDMILSON JOSÉ | C14: LTQ-0783 | D14: 0.60763889 | E14: 0.64583333 | F14: 0.66319444 | H14: =MOD(F14-E14, 1) -> 0.017361111
... A22: Zona Sul Loja 09 - Ipanema | B22: ALESSANDRA/ JONESON | C22: EBG-2D13 | D22: 0.66319444 | E22: 0.76041667 | F22: 0.78472222 | H22: =MOD(F22-E22, 1) -> 0.024305556
A23: Zona Sul Loja 12 - Leme | B23: MILTON | C23: KOP-4978 | D23: NÃO | E23: FOI AO | F23: CLIENTE | H23: 0
A24: Zona Sul Loja 38 - Copacabana | B24: FRANCISCO IRAN | C24: RJL-7D33 | D24: 0.65625 | E24: 0.69444444 | F24: 0.71180556 | H24: =MOD(F24-E24, 1) -> 0.017361111
A25: Zona Sul Loja 34 - Barra | B25: SÉRGIO JOSE DA SILVA (1º CARRO) | C25: LJS-2172 | D25: 0.69791667 | E25: 0.73958333 | F25: 0.76736111 | H25: =MOD(F25-E25, 1) -> 0.027777778
A26: Zona Sul Loja 35 - Barra | B26: FÁBIO / VLADIMIR (2º CARRO FL.34 ) | C26: KQY-9E24 | D26: 0.69097222 | E26: 0.74652778 | F26: 0.77083333 | H26: =MOD(F26-E26, 1) -> 0.024305556
A27: Zona Sul Loja 34 - Barra | B27: FÁBIO / VLADIMIR (2º CARRO FL.34 ) | C27: KQY-9E24 | D27: NÃO | E27: FOI AO | F27: CLIENTE | H27: 0
A28: Zona Sul Loja 43 - Barra (Península) | B28: FÁBIO / RODRIGO | C28: KWK-4593 | D28: 0.63888889 | E28: 0.68055556 | F28: 0.71180556 | H28: =MOD(F28-E28, 1) -> 0.03125
A29: Zona Sul Loja 47 - Catete | B29: CARLOS GONÇALVES | C29: LNU-9595 | D29: SEM | E29: RASTREADOR | H29: 0
A30: Zona Sul Loja 45 - Flamengo | B30: CARLOS GONÇALVES | C30: LNU-9595 | D30: SEM | E30: RASTREADOR | H30: 0
A31: Zona Sul Loja 19 - Copacabana | B31: DOUGLAS | C31: LTE-0A64 | D31: SEM | E31: RASTREADOR | H31: 0
A32: Zona Sul Loja 26 - Copacabana | B32: WILIAN FERES | C32: EFU-5704 | D32: 0.79861111 | E32: 0.83333333 | F32: 0.85416667 | H32: =MOD(F32-E32, 1) -> 0.020833333
A33: Zona Sul Loja 25 - Jd.Botânico | B33: RAPHAEL / LUIZ ALVES | C33: LCO-0978 | D33: 0.77430556 | E33: 0.84375 | F33: 0.85763889 | H33: =MOD(F33-E33, 1) -> 0.013888889
A34: Zona Sul Loja 06 - Gávea | B34: RAPHAEL / LUIZ ALVES | C34: LCO-0978 | D34: 0.77430556 | E34: 0.86111111 | F34: 0.87847222 | H34: =MOD(F34-E34, 1) -> 0.017361111
A35: Zona Sul Loja 31 - Jd.Botânico | B35: WANDERLEY | C35: AFY-7J99 | D35: 0.78472222 | E35: 0.84375 | F35: 0.86805556 | H35: =MOD(F35-E35, 1) -> 0.024305556
A36: Zona Sul Loja 22 - S.Conrado | B36: WANDERLEY | C36: AFY-7J99 | D36: 0.78472222 | E36: 0.87847222 | F36: 0.89583333 | H36: =MOD(F36-E36, 1) -> 0.017361111
A37: Zona Sul Loja 17 - Barra | B37: PAULO ROBERTO | C37: MDV-3746 | D37: SEM | E37: RASTREADOR | H37: 0
A38: Zona Sul Loja 44 - Barra | B38: PAULO ROBERTO | C38: MDV-3746 | D38: SEM | E38: RASTREADOR | H38: 0
A39: Zona Sul Loja 23 - Barra | B39: LUCIANO / ANDERSON | C39: LVE-0688 | D39: 0.78125 | E39: 0.82986111 | F39: 0.86111111 | H39: =MOD(F39-E39, 1) -> 0.03125
A40: Zona Sul Loja 10 - Recreio | B40: MOBRICI | C40: AOP-3C73 | D40: 0.77777778 | E40: 0.82986111 | F40: 0.86805556 | H40: =MOD(F40-E40, 1) -> 0.038194444
A41: Zona Sul Mega Box 2 - Recreio | B41: SIDNEI / DIEGO | C41: KQB-3F31 | D41: 0.78472222 | E41: 0.82291667 | F41: 0.85069444 | H41: =MOD(F41-E41, 1) -> 0.027777778
A42: Zona Sul Loja 40 - Ipanema | B42: EDUARDO / JOSENILDO ANISIO | C42: KRK-3D12 | D42: 0.64930556 | E42: 0.69791667 | F42: 0.73611111 | H42: =MOD(F42-E42, 1) -> 0.038194444
A43: Zona Sul Loja 03 - Copacabana I | B43: EVERTON | C43: CYB-3B90 | D43: 0.77083333 | E43: 0.84027778 | F43: 0.84722222 | H43: =MOD(F43-E43, 1) -> 0.0069444444
A44: Zona Sul Loja 05 - Copacabana III | B44: EVERTON | C44: CYB-3B90 | D44: 0.77083333 | E44: 0.85069444 | F44: 0.86111111 | H44: =MOD(F44-E44, 1) -> 0.010416667
A45: Zona Sul Loja 32 - Laranjeiras | B45: LUIZ / NILTON RODRIGUES | C45: AKZ-2594 | D45: 0.77083333 | E45: 0.85763889 | F45: 0.86458333 | H45: =MOD(F45-E45, 1) -> 0.0069444444
A46: Zona Sul Loja 20 - Botafogo | B46: LUIZ / NILTON RODRIGUES | C46: AKZ-2594 | D46: 0.77083333 | E46: 0.81597222 | F46: 0.83680556 | H46: =MOD(F46-E46, 1) -> 0.020833333
A47: Zona Sul Loja 42 - Botafogo | B47: RENATO | C47: JAJ-6B36 | D47: 0.79513889 | E47: 0.82638889 | F47: 0.85416667 | H47: =MOD(F47-E47, 1) -> 0.027777778
...

Sheet 08
A1: RELATÓRIO KPI - Zona Sul BENASSI
A2: REDES / FILIAIS | B2: MOTORISTA | C2: PLACA | D2: SAIDA CD | E2: CHD LOJA 1 | F2: SAIDA LOJA 1 | H2: TEMPO EM LOJA 1
A3: Zona Sul Loja 36 - Botafogo | B3: JOSUE DOS SANTOS | C3: BBH-1C94 | D3: 0.19097222 | E3: 0.21527778 | F3: 0.29861111 | H3: =MOD(F3-E3, 1) -> 0.083333333
A4: Zona Sul Loja 33 - Humaitá | B4: JÚLIO COUTO/INACIO ARAUJO | C4: LQU-5546 | D4: 0.15972222 | E4: 0.19097222 | F4: 0.29166667 | H4: =MOD(F4-E4, 1) -> 0.10069444
A5: Zona Sul Loja 30 - Laranjeiras | B5: SIDNEI ANTONIO MENDES | C5: LQE-5401 | D5: 0.19444444 | E5: 0.21875 | F5: 0.23611111 | H5: =MOD(F5-E5, 1) -> 0.017361111
A6: Zona Sul Loja 21 - Flamengo | B6: FÁBIO / LUIZ ALBERTO | C6: KQY-9E24 | D6: 0.20138889 | E6: 0.22569444 | F6: 0.31597222 | H6: =MOD(F6-E6, 1) -> 0.090277778
A7: Zona Sul Loja 04 - Copacabana II | B7: SANDRO EDUARDO/ MARCIO | C7: KVH-9J42 | D7: 0.26041667 | E7: 0.36111111 | F7: 0.38888889 | H7: =MOD(F7-E7, 1) -> 0.027777778
A8: Zona Sul Loja 18 - Copacabana | B8: ALEX | C8: LKW-2B80 | D8: 0.1875 | E8: 0.21875 | F8: 0.28819444 | H8: =MOD(F8-E8, 1) -> 0.069444444
A9: Zona Sul Loja 27 - Ipanema | C9: LQE5401 | D9: 0.19444444 | E9: 0.21875 | F9: 0.23611111 | H9: =MOD(F9-E9, 1) -> 0.017361111
A10: Zona Sul Loja 15 - Leblon | B10: JOSUÉ | C10: BBH1C94 | D10: 0.19097222 | E10: 0.34375 | F10: 0.36458333 | H10: =MOD(F10-E10, 1) -> 0.020833333
A11: Zona Sul Loja 07 - Leblon | B11: RAPHAEL / LUIZ ALVES | C11: LCO-0978 | D11: 0.22916667 | E11: 0.27430556 | F11: 0.44791667 | H11: =MOD(F11-E11, 1) -> 0.17361111
A12: Zona Sul Loja 48 - Recreio | B12: FRANCISCO IRAN | C12: RJL-7D33 | D12: 0.14583333 | E12: 0.17708333 | F12: 0.29166667 | H12: =MOD(F12-E12, 1) -> 0.11458333
A13: Zona Sul Loja 13 - Angra | B13: JULIO | C13: CZB-9J19 | D13: 0.11805556 | E13: 0.26041667 | F13: 0.30208333 | H13: =MOD(F13-E13, 1) -> 0.041666667
A14: Zona Sul Loja 28 - Urca | B14: FRANCISCO IRAN | C14: RJL-7D33 | D14: 0.63541667 | E14: 0.6875 | F14: 0.69791667 | H14: =MOD(F14-E14, 1) -> 0.010416667
A15: Zona Sul Loja 29 - Flamengo | B15: FRANCISCO IRAN | C15: RJL-7D33 | D15: 0.63541667 | E15: 0.70833333 | F15: 0.72222222 | H15: =MOD(F15-E15, 1) -> 0.013888889
A16: Zona Sul Mega Box 1 - Olaria | B16: DOUGLAS | C16: CZB-9J19 | D16: 0.63541667 | E16: 0.65625 | F16: 0.67361111 | H16: =MOD(F16-E16, 1) -> 0.017361111
A17: Zona Sul Mega Box 2 - Recreio | B17: DOUGLAS | C17: CZB-9J19 | D17: 0.63541667 | E17: 0.73958333 | F17: 0.75694444 | H17: =MOD(F17-E17, 1) -> 0.017361111
A18: Zona Sul Loja 07 - Leblon | B18: ALESSIO | C18: KQR-2J11 | D18: NÃO | E18: FOI AO | F18: CLIENTE | H18: =MOD(F18-E18, 1) -> #VALUE!
A19: Zona Sul Loja 11 - Leblon | B19: MARCIO / ERIVELTON (1º CARRO) | C19: KRH-5H67 | D19: 0.48958333 | E19: 0.53472222 | F19: 0.62847222 | H19: =MOD(F19-E19, 1) -> 0.09375
A20: Zona Sul Loja 11 - Leblon | B20: WILLIAM (2º CARRO) | C20: INW-8A51 | D20: 0.64583333 | E20: 0.70138889 | F20: 0.72222222 | H20: =MOD(F20-E20, 1) -> 0.020833333
A21: Zona Sul Loja 08 - Ipanema | B21: RAPHAEL / LUIZ ALVES | C21: LCO-0978 | D21: NÃO | E21: FOI AO | F21: CLIENTE | H21: =MOD(F21-E21, 1) -> #VALUE!
A22: Zona Sul Loja 14 - Leblon | B22: EDUARDO / JOSENILDO ANISIO | C22: KRK-3D12 | D22: 0.60763889 | E22: 0.67013889 | F22: 0.70833333 | H22: =MOD(F22-E22, 1) -> 0.038194444
A23: Zona Sul Loja 38 - Copacabana | B23: LUIZ / NILTON RODRIGUES | C23: AKZ-2594 | D23: 0.61111111 | E23: 0.67013889 | F23: 0.69791667 | H23: =MOD(F23-E23, 1) -> 0.027777778
A24: Zona Sul Loja 12 - Leme | B24: LUIZ / NILTON RODRIGUES | C24: AKZ-2594 | D24: 0.61111111 | E24: 0.71527778 | F24: 0.74305556 | H24: =MOD(F24-E24, 1) -> 0.027777778
A25: Zona Sul Loja 09 - Ipanema | B25: FÁBIO / VLADIMIR | C25: KQY-9E24 | D25: 0.63194444 | E25: 0.69097222 | F25: 0.72569444 | H25: =MOD(F25-E25, 1) -> 0.034722222
A26: Zona Sul Loja 01 - Ipanema | B26: FÁBIO / VLADIMIR | C26: KQY-9E24 | D26: 0.63194444 | E26: 0.72916667 | F26: 0.75347222 | H26: =MOD(F26-E26, 1) -> 0.024305556
A27: Zona Sul Loja 34 - Barra | B27: CARLOS GONÇALVES (1º CARRO) | C27: LNU-9595 | D27: NÃO | E27: FOI AO | F27: CLIENTE | H27: =MOD(F27-E27, 1) -> #VALUE!
A28: Zona Sul Loja 35 - Barra | B28: FÁBIO / RODRIGO (2º CARRO) | C28: KWK-4593 | D28: 0.66666667 | E28: 0.72569444 | F28: 0.76736111 | H28: =MOD(F28-E28, 1) -> 0.041666667
A29: Zona Sul Loja 34 - Barra | B29: FÁBIO / RODRIGO (2º CARRO) | C29: KWK-4593 | D29: NÃO | E29: FOI AO | F29: CLIENTE | H29: =MOD(F29-E29, 1) -> #VALUE!
A30: Zona Sul Loja 43 - Barra (Península) | B30: JÚLIO COUTO / INACIO ARAUJO | C30: LQU-5546 | D30: 0.62152778 | E30: 0.66666667 | F30: 0.69444444 | H30: =MOD(F30-E30, 1) -> 0.027777778
A31: Zona Sul Loja 47 - Catete | B31: MILTON | C31: KOP-4978 | D31: 0.65277778 | E31: 0.70138889 | F31: 0.72222222 | H31: =MOD(F31-E31, 1) -> 0.020833333
A32: Zona Sul Loja 45 - Flamengo | B32: SÉRGIO JOSE DA SILVA | C32: LJS-2172 | D32: 0.64930556 | E32: 0.70138889 | F32: 0.72222222 | H32: =MOD(F32-E32, 1) -> 0.020833333
A33: Zona Sul Loja 19 - Copacabana | B33: TIAGO DA COSTA | C33: TTX-9E34 | D33: SEM | E33: RASTREADOR | H33: =MOD(F33-E33, 1) -> #VALUE!
A34: Zona Sul Loja 03 - Copacabana I | B34: ALEX | C34: LKW-2B80 | D34: 0.74652778 | E34: 0.80208333 | F34: 0.81597222 | H34: =MOD(F34-E34, 1) -> 0.013888889
A35: Zona Sul Loja 05 - Copacabana III | B35: ALEX | C35: LKW-2B80 | D35: 0.74652778 | E35: 0.81944444 | F35: 0.82986111 | H35: =MOD(F35-E35, 1) -> 0.010416667
A36: Zona Sul Loja 25 - Jd.Botânico | B36: SIDNEI / DIEGO | C36: KQB-3F31 | D36: 0.81944444 | E36: 0.89930556 | F36: 0.92013889 | H36: =MOD(F36-E36, 1) -> 0.020833333
A37: Zona Sul Loja 22 - S.Conrado | B37: SIDNEI / DIEGO | C37: KQB-3F31 | D37: 0.81944444 | E37: 0.92708333 | F37: 0.94097222 | H37: =MOD(F37-E37, 1) -> 0.013888889
A38: Zona Sul Loja 06 - Gávea | B38: EVERTON | C38: CYB-3B90 | D38: 0.77777778 | E38: 0.82638889 | F38: 0.84722222 | H38: =MOD(F38-E38, 1) -> 0.020833333
A39: Zona Sul Loja 31 - Jd.Botânico | B39: EVERTON | C39: CYB-3B90 | D39: 0.77777778 | E39: 0.85763889 | F39: 0.86458333 | H39: =MOD(F39-E39, 1) -> 0.0069444444
A40: Zona Sul Loja 23 - Barra | B40: MARCIO | C40: LTH-4J15 | D40: 0.76041667 | E40: 0.80555556 | F40: 0.84027778 | H40: =MOD(F40-E40, 1) -> 0.034722222
...

Sheet 09
A1: RELATÓRIO KPI - Zona Sul BENASSI
A2: REDES / FILIAIS | B2: MOTORISTA | C2: PLACA | D2: SAIDA CD | E2: CHD LOJA 1 | F2: SAIDA LOJA 1 | H2: TEMPO EM LOJA 1
A3: Zona Sul Loja 36 - Botafogo | B3: JOSUE DOS SANTOS | C3: BBH-1C94 | D3: 0.19097222 | E3: 0.21527778 | F3: 0.30208333 | H3: =MOD(F3-E3, 1) -> 0.086805556
A4: Zona Sul Loja 33 - Humaitá | B4: JÚLIO COUTO/INACIO ARAUJO | C4: LQU-5546 | D4: 0.16319444 | E4: 0.19097222 | F4: 0.29166667 | H4: =MOD(F4-E4, 1) -> 0.10069444
A5: Zona Sul Loja 30 - Laranjeiras | B5: SIDNEI ANTONIO MENDES | C5: LQE-5401 | D5: 0.19097222 | E5: 0.21527778 | F5: 0.22916667 | H5: =MOD(F5-E5, 1) -> 0.013888889
A6: Zona Sul Loja 21 - Flamengo | B6: FÁBIO P. / LUIZ ALBERTO | C6: KQY-9E24 | D6: 0.21875 | E6: 0.24305556 | F6: 0.29861111 | H6: =MOD(F6-E6, 1) -> 0.055555556
A7: Zona Sul Loja 04 - Copacabana II | B7: SANDRO EDUARDO/ MARCIO | C7: KVH-9J42 | D7: 0.20833333 | E7: 0.23611111 | F7: 0.35416667 | H7: =MOD(F7-E7, 1) -> 0.11805556
A8: Zona Sul Loja 18 - Copacabana | B8: WILLIAM / EDMILSON JOSÉ | C8: LTQ-0783 | D8: 0.25 | E8: 0.28125 | F8: 0.30555556 | H8: =MOD(F8-E8, 1) -> 0.024305556
A9: Zona Sul Loja 07 - Leblon | B9: RAPHAEL /LUIZ ALVES (1º CARRO) | C9: LCO-0978 | D9: 0.27430556 | E9: 0.34722222 | F9: 0.37847222 | H9: =MOD(F9-E9, 1) -> 0.03125
A10: Zona Sul Loja 07 - Leblon | B10: ALEX (2º CARRO) | C10: LKW-2B80 | D10: 0.19097222 | E10: 0.22222222 | F10: 0.34375 | H10: =MOD(F10-E10, 1) -> 0.12152778
A11: Zona Sul Loja 48 - Recreio | B11: FRANCISCO IRAN | C11: RJL-7D33 | D11: 0.14583333 | E11: 0.17708333 | F11: 0.29513889 | H11: =MOD(F11-E11, 1) -> 0.11805556
A12: Zona Sul Loja 13 - Angra | B12: JULIO | C12: CZB-9J19 | D12: 0.13541667 | E12: 0.26388889 | F12: 0.30208333 | H12: =MOD(F12-E12, 1) -> 0.038194444
A13: Zona Sul Loja 28 - Urca | B13: WILLIAM / EDMILSON JOSÉ | C13: LTQ-0783 | D13: 0.47916667 | E13: 0.53472222 | F13: 0.54166667 | H13: =MOD(F13-E13, 1) -> 0.0069444444
A14: Zona Sul Loja 29 - Flamengo | B14: ALEX | C14: LKW-2B80 | D14: 0.56944444 | E14: 0.61111111 | F14: 0.63194444 | H14: =MOD(F14-E14, 1) -> 0.020833333
... A20: Zona Sul Loja 14 - Leblon | B20: MILTON | C20: KOP-4978 | D20: 0.47569444 | E20: 0.51736111 | F20: 0.54166667 | H20: =MOD(F20-E20, 1) -> 0.024305556
A21: Zona Sul Loja 09 - Ipanema | B21: HLOG /MARCOS VINICIUS | C21: UGA-1D55 | D21: NÃO | E21: FOI AO | F21: CLIENTE | H21: =MOD(F21-E21, 1) -> #VALUE!
A22: Zona Sul Loja 38 - Copacabana | B22: LUIZ / NILTON RODRIGUES | C22: AKZ-2594 | D22: NÃO | E22: FOI AO | F22: CLIENTE | H22: =MOD(F22-E22, 1) -> #VALUE!
A23: Zona Sul Loja 12 - Leme | B23: HLOG /MARCIO LUIZ | C23: UBG-7F79 | D23: 0.62152778 | E23: 0.67013889 | F23: 0.71527778 | H23: =MOD(F23-E23, 1) -> 0.045138889
A24: Zona Sul Loja 34 - Barra | B24: DOUGLAS (1º CARRO) | C24: CZB-9J19 | D24: 0.62152778 | E24: 0.66666667 | F24: 0.6875 | H24: =MOD(F24-E24, 1) -> 0.020833333
A25: Zona Sul Loja 34 - Barra | B25: MOBRICI (2º CARRO) | C25: AOP-3C73 | D25: 0.79861111 | E25: 0.85069444 | F25: 0.86805556 | H25: =MOD(F25-E25, 1) -> 0.017361111
A26: Zona Sul Loja 43 - Barra (Península) | B26: SÉRGIO JOSE DA SILVA | C26: LJS-2172 | D26: 0.68055556 | E26: 0.72222222 | F26: 0.75694444 | H26: =MOD(F26-E26, 1) -> 0.034722222
A27: Zona Sul Loja 35 - Barra | B27: FÁBIO / VLADIMIR | C27: KQY-9E24 | D27: 0.61111111 | E27: 0.66319444 | F27: 0.72569444 | H27: =MOD(F27-E27, 1) -> 0.0625
A28: Zona Sul Loja 40 - Ipanema | B28: CARLOS GONÇALVES (1º CARRO) | C28: LNU-9595 | D28: SEM | E28: RASTREADOR | H28: =MOD(F28-E28, 1) -> #VALUE!
A29: Zona Sul Loja 40 - Ipanema | B29: HLOG / ALEXANDRE / MARCOS FERNANDO (1º CARRO) | C29: QSS-1E48 | D29: 0.69097222 | E29: 0.72916667 | F29: 0.77430556 | H29: =MOD(F29-E29, 1) -> 0.045138889
A30: Zona Sul Loja 45 - Flamengo | B30: EDUARDO (1º CARRO) | C30: QAH-2H50 | D30: SEM | E30: RASTREADOR | H30: =MOD(F30-E30, 1) -> #VALUE!
A31: Zona Sul Loja 45 - Flamengo | B31: HLOG /FABRICIO | C31: FKY-8H51 | D31: 0.71875 | E31: 0.75694444 | F31: 0.84722222 | H31: =MOD(F31-E31, 1) -> 0.090277778
A32: Zona Sul Loja 26 - Copacabana | B32: LUCIANO / ANDERSON | C32: LVE-0688 | D32: 0.73958333 | E32: 0.78125 | F32: 0.82986111 | H32: =MOD(F32-E32, 1) -> 0.048611111
A33: Zona Sul Loja 19 - Copacabana | B33: EDUARDO (1º CARRO) | C33: LQA-5883 | D33: SEM | E33: RASTREADOR | H33: =MOD(F33-E33, 1) -> #VALUE!
A34: Zona Sul Loja 19 - Copacabana | B34: SIDNEI / AGNALDO (2º CARRO) | C34: LKR-5990 | D34: SEM | E34: RASTREADOR | H34: =MOD(F34-E34, 1) -> #VALUE!
A35: Zona Sul Loja 05 - Copacabana III | B35: FELIPE SILVA | C35: KUL-1425 | D35: NÃO | E35: FOI AO | F35: CLIENTE | H35: =MOD(F35-E35, 1) -> #VALUE!
A36: Zona Sul Loja 03 - Copacabana I | B36: WILIAN FERES | C36: EFU-5704 | D36: 0.80902778 | E36: 0.84375 | F36: 0.86111111 | H36: =MOD(F36-E36, 1) -> 0.017361111
A37: Zona Sul Loja 20 - Botafogo | B37: ALESSANDRA/ JONESON | C37: EBG-2D13 | D37: 0.76388889 | E37: 0.79861111 | H37: =MOD(F37-E37, 1) -> 0.20138889
A38: Zona Sul Loja 25 - Jd.Botânico | B38: SIDNEI / DIEGO | C38: KQB-3F31 | D38: 0.83333333 | E38: 0.86805556 | F38: 0.91666667 | H38: =MOD(F38-E38, 1) -> 0.048611111
A39: Zona Sul Loja 22 - S.Conrado | B39: RAPHAEL / DANIEL | C39: LKV-5067 | D39: 0.77083333 | E39: 0.82291667 | F39: 0.85416667 | H39: =MOD(F39-E39, 1) -> 0.03125
A40: Zona Sul Loja 31 - Jd.Botânico | B40: EDUARDO / JOSENILDO ANISIO | C40: KRK-3D12 | D40: 0.73958333 | E40: 0.77777778 | F40: 0.79861111 | H40: =MOD(F40-E40, 1) -> 0.020833333
A41: Zona Sul Loja 17 - Barra | B41: EDUARDO / JOSENILDO ANISIO | C41: KXX-6922 | D41: SEM | E41: RASTREADOR | H41: =MOD(F41-E41, 1) -> #VALUE!
A42: Zona Sul Loja 23 - Barra | B42: TIAGO DA COSTA | C42: TTX-9E34 | D42: SEM | E42: RASTREADOR | H42: =MOD(F42-E42, 1) -> #VALUE!
A43: Zona Sul Loja 44 - Barra | B43: MILTON | C43: KOP-4978 | D43: 0.73263889 | E43: 0.78819444 | F43: 0.82291667 | H43: =MOD(F43-E43, 1) -> 0.034722222
A44: Zona Sul Loja 10 - Recreio | B44: PAULO ROBERTO (1º CARRO) | C44: MDV-3746 | D44: SEM | E44: RASTREADOR | H44: =MOD(F44-E44, 1) -> #VALUE!
A45: Zona Sul Mega Box 2 - Recreio | B45: RAPHAEL / LUIZ ANTONIO ALVES (2ºCARRO) | C45: KMY-5561 | D45: 0.75694444 | E45: 0.79861111 | F45: 0.83333333 | H45: =MOD(F45-E45, 1) -> 0.034722222
...

Sheet 10
A1: RELATÓRIO KPI - Zona Sul BENASSI
A2: REDES / FILIAIS | B2: MOTORISTA | C2: PLACA | D2: SAIDA CD | E2: CHD LOJA 1 | F2: SAIDA LOJA 1 | H2: TEMPO EM LOJA 1
A3: Zona Sul Loja 18 - Copacabana | B3: ALEX | C3: LKW-2B80 | D3: 0.22569444 | E3: 0.26041667 | F3: 0.78958333 | H3: =MOD(F3-E3, 1) -> 0.52916667
A4: Zona Sul Loja 04 - Copacabana II | B4: JOSUE DOS SANTOS | C4: BBH-1C94 | D4: 0.24652778 | E4: 0.27777778 | F4: 0.35416667 | H4: =MOD(F4-E4, 1) -> 0.076388889
A5: Zona Sul Loja 30 - Laranjeiras | B5: SIDNEI ANTONIO MENDES | C5: LQE-5401 | D5: 0.16319444 | E5: 0.1875 | F5: 0.22916667 | H5: =MOD(F5-E5, 1) -> 0.041666667
A6: Zona Sul Loja 21 - Flamengo | B6: FÁBIO P. /RODRIGO | C6: KWK-4593 | D6: 0.22222222 | E6: 0.26388889 | F6: 0.34375 | H6: =MOD(F6-E6, 1) -> 0.079861111
A7: Zona Sul Loja 33 - Humaitá | B7: FÁBIO / VLADIMIR | C7: KQY-9E24 | D7: 0.20833333 | E7: 0.23611111 | F7: 0.34375 | H7: =MOD(F7-E7, 1) -> 0.10763889
A8: Zona Sul Loja 36 - Botafogo | B8: RAPHAEL /LUIZ ALVES | C8: LCO-0978 | D8: 0.26736111 | E8: 0.36111111 | F8: 0.41666667 | H8: =MOD(F8-E8, 1) -> 0.055555556
A9: Zona Sul Loja 48 - Recreio | B9: FRANCISCO IRAN | C9: RJL-7D33 | D9: 0.18402778 | E9: 0.21180556 | F9: 0.28819444 | H9: =MOD(F9-E9, 1) -> 0.076388889
A10: Zona Sul Loja 13 - Angra | B10: JULIO | C10: CZB-9J19 | D10: 0.0034722222 | E10: 0.27430556 | F10: 0.30902778 | H10: =MOD(F10-E10, 1) -> 0.034722222
H11: =MOD(F11-E11, 1) -> 0
H12: =MOD(F12-E12, 1) -> 0
H13: =MOD(F13-E13, 1) -> 0
H14: =MOD(F14-E14, 1) -> 0
H15: =MOD(F15-E15, 1) -> 0
H16: =MOD(F16-E16, 1) -> 0
H17: =MOD(F17-E17, 1) -> 0
H18: =MOD(F18-E18, 1) -> 0
H19: =MOD(F19-E19, 1) -> 0
H20: =MOD(F20-E20, 1) -> 0
H21: =MOD(F21-E21, 1) -> 0
H22: =MOD(F22-E22, 1) -> 0
... H69: =MOD(F69-E69, 1) -> 0

Sheet 11
A1: RELATÓRIO KPI - Zona Sul BENASSI
A2: REDES / FILIAIS | B2: MOTORISTA | C2: PLACA | D2: SAIDA CD | E2: CHD LOJA 1 | F2: SAIDA LOJA 1 | H2: TEMPO EM LOJA 1
A3: Zona Sul Loja 27 - Ipanema | B3: FÁBIO / LUIZ ALBERTO | C3: KQY-9E24 | D3: 0.20833333 | E3: 0.23958333 | F3: 0.25694444 | H3: =MOD(F3-E3, 1) -> 0.017361111
A4: Zona Sul Loja 21 - Flamengo | B4: MOBRICI | C4: AOP-3C73 | D4: NÃO | E4: FOI AO | F4: CLIENTE | H4: =MOD(F4-E4, 1) -> #VALUE!
A5: Zona Sul Loja 30 - Laranjeiras | B5: SIDNEI ANTONIO MENDES | C5: LQE-5401 | D5: NÃO | E5: FOI AO | F5: CLIENTE | H5: =MOD(F5-E5, 1) -> #VALUE!
A6: Zona Sul Loja 27 - Ipanema | B6: JOSUE DOS SANTOS | C6: BBH-1C94 | D6: NÃO | E6: FOI AO | F6: CLIENTE | H6: =MOD(F6-E6, 1) -> #VALUE!
A7: Zona Sul Loja 15 - Leblon | B7: JOSUE DOS SANTOS | C7: BBH-1C94 | D7: 0.21180556 | E7: 0.26736111 | F7: 0.29513889 | H7: =MOD(F7-E7, 1) -> 0.027777778
A8: Zona Sul Loja 04 - Copacabana II | B8: SANDRO EDUARDO / MARCIO | C8: KVH-9J42 | D8: NÃO | E8: FOI AO | F8: CLIENTE | H8: =MOD(F8-E8, 1) -> #VALUE!
A9: Zona Sul Loja 07 - Leblon | B9: RAPHAEL /LUIZ ALVES | C9: LCO-0978 | D9: 0.21875 | E9: 0.26388889 | F9: 0.45138889 | H9: =MOD(F9-E9, 1) -> 0.1875
A10: Zona Sul Loja 48 - Recreio | B10: FRANCISCO IRAN | C10: RJL-7D33 | D10: NÃO | E10: FOI AO | F10: CLIENTE | H10: =MOD(F10-E10, 1) -> #VALUE!
A11: Zona Sul Loja 13 - Angra | B11: JULIO | C11: CZB-9J19 | D11: NÃO | E11: FOI AO | F11: CLIENTE | H11: =MOD(F11-E11, 1) -> #VALUE!
A12: Zona Sul Loja 15 - Leblon | B12: WILLIAM / EDMILSON JOSÉ | C12: LTQ-0783 | D12: 0.47916667 | E12: 0.54861111 | F12: 0.55902778 | H12: =MOD(F12-E12, 1) -> 0.010416667
A13: Zona Sul Loja 25 - Jd.Botânico | B13: WILLIAM / EDMILSON JOSÉ | C13: LTQ-0783 | D13: 0.47916667 | E13: 0.53125 | F13: 0.54513889 | H13: =MOD(F13-E13, 1) -> 0.013888889
A14: Zona Sul Loja 04 - Copacabana II | B14: ALEX | C14: LKW-2B80 | D14: 0.46180556 | E14: 0.50347222 | F14: 0.51736111 | H14: =MOD(F14-E14, 1) -> 0.013888889
A15: Zona Sul Loja 18 - Copacabana | B15: ALEX | C15: LKW-2B80 | D15: 0.46180556 | E15: 0.52083333 | F15: 0.54166667 | H15: =MOD(F15-E15, 1) -> 0.020833333
A16: Zona Sul Loja 10 - Recreio | B16: FÁBIO P. /RODRIGO | C16: KWK-4593 | D16: 0.45486111 | E16: 0.53472222 | F16: 0.55208333 | H16: =MOD(F16-E16, 1) -> 0.017361111
A17: Zona Sul Loja 17 - Barra | B17: FÁBIO P. /RODRIGO | C17: KWK-4593 | D17: 0.45486111 | E17: 0.49305556 | F17: 0.51736111 | H17: =MOD(F17-E17, 1) -> 0.024305556
A18: Zona Sul Loja 46 - Botafogo | B18: JÚLIO COUTO / INACIO ARAUJO | C18: LQU-5546 | D18: 0.46180556 | E18: 0.5 | F18: 0.51736111 | H18: =MOD(F18-E18, 1) -> 0.017361111
A19: Zona Sul Loja 36 - Botafogo | B19: JÚLIO COUTO / INACIO ARAUJO | C19: LQU-5546 | D19: 0.46180556 | E19: 0.53472222 | F19: 0.54861111 | H19: =MOD(F19-E19, 1) -> 0.013888889
A20: Zona Sul Loja 1129 - Olaria | B20: SÉRGIO JOSE DA SILVA | C20: LJS-2172 | D20: 0.50694444 | E20: 0.52083333 | F20: 0.53125 | H20: =MOD(F20-E20, 1) -> 0.010416667
A21: Zona Sul Mega Box 1 - Olaria | B21: SÉRGIO JOSE DA SILVA | C21: LJS-2172 | D21: 0.50694444 | E21: 0.53472222 | F21: 0.54513889 | H21: =MOD(F21-E21, 1) -> 0.010416667
A22: Zona Sul Loja 47 - Catete | B22: SIDNEI ANTONIO | C22: LQE-5401 | D22: 0.49652778 | E22: 0.53125 | F22: 0.5625 | H22: =MOD(F22-E22, 1) -> 0.03125
A23: Zona Sul Loja 31 - Jd.Botânico | B23: SIDNEI ANTONIO | C23: LQE-5401 | D23: 0.49652778 | E23: 0.58333333 | F23: 0.62152778 | H23: =MOD(F23-E23, 1) -> 0.038194444
... A25: Zona Sul Loja 19 - Copacabana | B25: LUIZ / NILTON RODRIGUES | C25: AKZ-2594 | D25: 0.46180556 | E25: 0.50694444 | F25: 0.55555556 | H25: =MOD(F25-E25, 1) -> 0.048611111
A26: Zona Sul Mega Box 2 - Recreio | B26: EDUARDO | C26: LQA-5883 | D26: NÃO | E26: FOI AO | F26: CLIENTE | H26: =MOD(F26-E26, 1) -> #VALUE!
A27: Zona Sul Loja 34 - Barra | B27: FRANCISCO IRAN | C27: RJL-7D33 | D27: 0.46180556 | E27: 0.5 | F27: 0.52430556 | H27: =MOD(F27-E27, 1) -> 0.024305556
A28: Zona Sul Loja 28 - Urca | B28: HLOG / BRUNO PEREIRA | C28: UBF-5G34 | D28: SEM | E28: RASTREADOR | H28: =MOD(F28-E28, 1) -> #VALUE!
A29: Zona Sul Loja 29 - Flamengo | B29: MILTON | C29: KOP-4978 | D29: NÃO | E29: FOI AO | F29: CLIENTE | H29: =MOD(F29-E29, 1) -> #VALUE!
A30: Zona Sul Loja 28 - Urca | B30: MILTON | C30: KOP-4978 | D30: NÃO | E30: FOI AO | F30: CLIENTE | H30: =MOD(F30-E30, 1) -> #VALUE!
A31: Zona Sul Loja 07 - Leblon | B31: ALESSIO | C31: KQR-2J11 | D31: NÃO | E31: FOI AO | F31: CLIENTE | H31: =MOD(F31-E31, 1) -> #VALUE!
